Workbook
Name _Hlk158276605: Planilha1!$B$132

Sheet Planilha1
K2: CONTRATO DE PRESTAÇÃO DE SERVIÇOS EDUCACIONAIS EXTRACURRICULARES
K4: 2026
U7: QUADRO DESCRITIVO | AV7: =(IF(C10="","BRANCO",""))
B9: Matrícula Aluno(a) | L9: Nome do(a) Aluno(a)
M10: =IFERROR(VLOOKUP(C10,Planilha3!A:L,2,FALSE),"")
B12: Série/Ano | U12: Data de Nascimento
C13: =IFERROR(VLOOKUP(C10,Planilha3!A:L,3,FALSE),"") | V13: =IFERROR(VLOOKUP(C10,Planilha3!A:M,13,FALSE),"")
B15: CONTRATANTE / Responsável Legal
C16: =IFERROR(VLOOKUP(C10,Planilha3!A:L,4,FALSE),"")
B18: Nº CPF | U18: Nº RG | AI18: Telefonde de Contato
B21: Endereço
C22: =IFERROR(VLOOKUP(C10,Planilha3!A:L,8,FALSE),"")
B24: Bairro | U24: Cidade | AP24: UF | AT24: CEP
C25: =IFERROR(VLOOKUP(Planilha1!C10,Planilha3!A:L,9,FALSE),"") | V25: =IFERROR(VLOOKUP(C10,Planilha3!A:L,10,FALSE),"") | AP25: =IFERROR(VLOOKUP(C10,Planilha3!A:L,11,FALSE),"") | AT25: =IFERROR(VLOOKUP(C10,Planilha3!A:L,12,FALSE),"")
B29: ATIVIDADE | Z29: Turma | AQ29: Professor(a)
AA30: =IF(AV7="BRANCO","",IFERROR(VLOOKUP(Planilha2!A13,Planilha2!A1:F9,3,FALSE),"")) | AR30: Fabiano
B32: Dia/Semana | Z32: Horário
C33: =IF(AV7="BRANCO","",IFERROR(VLOOKUP(Planilha2!A13,Planilha2!A1:G9,4,FALSE),"")) | AA33: =IF(AV7="BRANCO","",IFERROR(VLOOKUP(Planilha2!A13,Planilha2!A1:G9,5,FALSE),""))
B35: Valor da Parcela - R$ | M35: Nº de Parcelas | U35: Valor Total - R$ | AF35: ="Vencimento parc.1/"&N36 | AQ35: ="Vencimento parc."&N36&"/"&N36
C36: =IF(AV7="BRANCO","",IFERROR(VLOOKUP(Planilha2!A13,Planilha2!A1:G9,6,FALSE),"")) | N36: 7 | V36: =IF(AV7="BRANCO","",N36*C36) | AG36: 46152 | AR36: 46336
B39: CONTRATADA: Ordem Auxiliadora das Senhoras Evangélicas, mantenedora do Instituto Educacional Luterano, pessoa jurídica de direito privado, inscrita no CNPJ/MF: sob nº 60.761.657/0005-27, com sede à Av Hermann Teles Ribeiro, 162, Vila Romanópolis, Ferraz de Vasconcelos, SP.
B45: As partes acima identificadas, através de seus representantes legais, têm entre si justas e acertadas o presente Contrato de Prestação de Serviços, que se regerá pelas cláusulas e condições seguintes.
B49: I – OBJETO:
B51: A CONTRATADA prestará serviços de treinamento e capacitação para o período letivo de 2026 ao(s) Beneficiário(a)(s), na forma de cursos extracurriculares de caráter, esportivo, artístico e cultural, em locais que se fizerem necessários conforme atividade praticada.
B58: § 1º - O presente contrato é celebrado sob a égide da legislação pertinente, sendo certo que os valores avençados neste instrumento são de conhecimento prévio do CONTRATANTE, nos termos da legislação vigente.
B63: § 2º - Os cursos serão ministrados nas instalações do Colégio, ficando o CONTRATANTE desde já ciente de que o(a)(s) aluno(a)(s) beneficiário(a)(s) estará(ao) sujeito(s) às normas do estabelecimento de ensino onde serão ministrados os cursos, as quais estão à disposição do CONTRATANTE, e cujas determinações integram o presente instrumento para aplicação subsidiária e em casos omissos.
B70: § 3º - Não estão incluídos neste contrato os materiais e vestuários específicos necessários à participação nos cursos, os opcionais e de uso facultativo para o(a)(s) aluno(a)(s), transporte, refeições e eventual material de uso individual.
B75: II - PROCEDIMENTO DE MATRÍCULA:
B77: § 1º - O procedimento de matrícula do(a)(s) Beneficiário(a)(s) inicia-se com o contrato corretamente preenchido pelo CONTRATANTE, bem como acompanhado de todos os documentos exigidos e reputa-se concluída com o pagamento da matrícula.
B82: § 2º - Ficará ao critério da CONTRATADA o deferimento ou renovação da matrícula do(a)(s) Beneficiário(a)(s), sendo motivos especiais de indeferimento ou recusa à renovação a inexistência do número mínimo necessário de alunos para a viabilização econômica de determinada turma e o inadimplemento de quaisquer obrigações anteriormente assumidas.
B88: § 3º - O CONTRATANTE assume total responsabilidade pela veracidade e precisão das informações prestadas por ocasião do requerimento de matrícula.
B92: § 4º - Não haverá restituição de valores pagos após 07 dias do início das aulas.
... B164: Elegem as partes a Comarca de Ferraz de Vasconcelos, Estado de São Paulo, para dirimir quaisquer dúvidas ou divergências oriundas do presente contrato, renunciando a qualquer outro por mais privilegiado que o seja.
A170: Por estarem justas e contratadas as partes, firmam o presente, em 2 (duas) vias de igual teor e forma, juntamente com 2 (duas) testemunhas.
B176: ="Ferraz de Vasconcelos, " -> Ferraz de Vasconcelos, | P176: =TODAY() | X176: ="."
B184: =C16 | AD184: Ordem Auxiliadora das Senhoras Evangélicas
B185: CONTRATANTE | AD185: CONTRATADA
B189: Testemunhas:
B196: Nome | AD196: Nome
B198: CPF | AD198: CPF
...

Sheet Planilha3
A1: Mat | B1: Nome | C1: DescClasse | D1: NomeResp | E1: TelefoneResp | F1: cpfresp | G1: RGResp | H1: Endereco | I1: Bairro | J1: Cidade | K1: Estado | L1: CEP | M1: DATA NASC

Sheet Planilha2
A1: 1
A2: 2 | B2: ⚽ Futsal | C2: Todas | D2: 📅 Terças e quintas | E2: ⏰ 18h às 19h40 | F2: 110 | G2: Fabiano
A3: 3 | B3: 🥋 Judô Baby | C3: Educação Infantil | D3: 📅 Terças-feiras | E3: ⏰ 11h às 12h | F3: 60 | G3: Fabiano
A4: 4 | B4: 🥋 Judô Infantil | C4: 1º ao 5º ano | D4: 📅 Terças-feiras | E4: ⏰ 9h30 às 11h | F4: 110 | G4: Fabiano
A5: 5 | B5: 🩰 Ballet Baby Class | C5: Educação Infantil | D5: 📅 Sextas-feiras | E5: ⏰ 11h às 12h | F5: 60 | G5: Kaylane
A6: 6 | B6: 🩰 Ballet Infantil | C6: 1º ao 3º ano | D6: 📅 Segundas e quintas | E6: ⏰ 18h às 19h | F6: 110 | G6: Larissa
A7: 7 | B7: 🩰 Ballet Infanto Juvenil | C7: 4º e 5º ano | D7: 📅 Terças-feiras | E7: ⏰ 18h às 20h | F7: 110 | G7: Larissa
A8: 8 | B8: 🩰 Ballet Juvenil | C8: 6º ao 9º ano | D8: 📅 Terças e quintas | E8: ⏰ 12h30 às 13h30 | F8: 110 | G8: Kaylane
A9: 9 | B9: 🩰 Ballet Juvenil Preparatório | C9: 7º ano ao Ensino Médio | D9: 📅 Quartas-feiras | E9: ⏰ 18h às 19h | F9: 110 | G9: Larissa
C11: =TODAY()
A12: opção | B12: descrição | C12: data matrícula (até) | D12: entrada | E12: nº parcelas | F12: valor parcela
A13: 6 | B13: Futsal | C13: 46112 | D13: 110 | E13: =IF(C11<C13,9,IF(C11<C14,8,IF(C11<C15,7,IF(C11<C16,6,IF(C11<C17,4,IF(C11<C18,3,IF(C11<C19,2,IF(C11<C20,1,0)))))))) | F13: 110 | H13: 1100 | I13: 9 | J13: =H13/I13 | K13: 10 | L13: =H13/K13 | N13: 46091
A14: 1 | B14: Futsal | C14: 46142 | D14: 110 | E14: 8 | F14: 110 | H14: =$J$13*I14 | I14: =I13-1 | K14: =K13-1 | L14: =H14/K14 | M14: =9*110 | N14: 46122
A15: 1 | B15: Futsal | C15: 46173 | D15: 110 | E15: 7 | F15: 110 | H15: =$J$13*I15 | I15: =I14-1 | K15: =K14-1 | L15: =H15/K15 | M15: =8*110 | N15: 46152
A16: 1 | B16: Futsal | C16: 46203 | D16: 110 | E16: 6 | F16: 110 | H16: =$J$13*I16 | I16: =I15-1 | K16: =K15-1 | L16: =H16/K16 | M16: =7*110 | N16: 46183
A17: 1 | B17: Futsal | C17: 46265 | D17: 110 | E17: 4 | F17: 110 | H17: =$J$13*I17 | I17: =I16-1 | K17: 5 | L17: =H17/K17 | M17: =5*110 | N17: 46244
A18: 1 | B18: Futsal | C18: 46295 | D18: 110 | E18: 3 | F18: 110 | H18: =$J$13*I18 | I18: =I17-1 | K18: =K17-1 | L18: =H18/K18 | M18: =K18*110 | N18: 46275
A19: 1 | B19: Futsal | C19: 46326 | D19: 110 | E19: 2 | F19: 110 | H19: =$J$13*I19 | I19: =I18-1 | K19: =K18-1 | L19: =H19/K19 | M19: =K19*110 | N19: 46305
A20: 1 | B20: Futsal | C20: 46356 | D20: 110 | E20: 1 | F20: 110 | H20: =$J$13*I20 | I20: =I19-1 | K20: =K19-1 | L20: =H20/K20 | M20: =K20*110 | N20: 46336
A21: 1 | B21: Futsal | C21: 46387 | D21: 110 | E21: 0 | F21: 110 | H21: =$J$13*I21 | I21: =I20-1 | K21: =K20-1 | L21: =H21/K21 | M21: =K21*110 | N21: 46366
